Workbook

Sheet Planilha1
A1: Nº recibo | B1: Limite máximo | C1: sem juros/com juros | D1: NomeArquivo | E1: status | F1: Mensagem | G1: TipoReferencia | H1: NumeroReferencia | I1: Aplica | J1: Meio de Envio | K1: Tipo Destino | L1: Nome | M1: E-mail Destino | N1: E-mail Copia | O1: ModeloDescricao | P1: ModeloDescricao2 | Q1: Aviso | R1: status | S1: Upload | T1: ERRO | U1: linha
A2: 636905030 | B2: 45843 | C2: Sim | D2: 636905030 | G2: Apólice | H2: 128960940 | I2: 0 | J2: 6-Correio Electronico | K2: 7-Outros | L2: Captura de parcela rejeitada - Apólice 128960940 - ANDRE LUIZ KRAINZ | M2: contato@segurosvieira.com.br | O2: 57 | P2: 5705 | Q2: Prezado(a), Identificamos uma falha na tentativa de captura da parcela 11 da apólice em questão, para não penalizar o segurado com cobrança de juros, emitimos novo boleto que encontra-se em anexo e dispoível na Ficha Gestão da apólice, por favor encaminhá-lo ao pagador. Caso o cliente já tenha realizado o pagamento, pedimos que desconsidere o boleto ou entre em contato conosco através do gestor de operações na opção "Cobrança Indevida". Pedimos desculpas pelo transtorno causado. Att. Departamento de Cobrança "Este e-mail é um envio automático, favor não responder.” | R2: Processado | S2: Processado | U2: 1
A3: 655634545 | B3: 45843 | C3: Sim | D3: 655634545 | G3: Apólice | H3: 129352066 | I3: 0 | J3: 6-Correio Electronico | K3: 7-Outros | L3: Captura de parcela rejeitada - Apólice 129352066 - LUIZ MARGALLO DE CASTRO | M3: andrea@thompsonseguros.com.br | O3: 57 | P3: 5705 | Q3: Prezado(a), Identificamos uma falha na tentativa de captura da parcela 10 da apólice em questão, para não penalizar o segurado com cobrança de juros, emitimos novo boleto que encontra-se em anexo e dispoível na Ficha Gestão da apólice, por favor encaminhá-lo ao pagador. Caso o cliente já tenha realizado o pagamento, pedimos que desconsidere o boleto ou entre em contato conosco através do gestor de operações na opção "Cobrança Indevida". Pedimos desculpas pelo transtorno causado. Att. Departamento de Cobrança "Este e-mail é um envio automático, favor não responder.” | R3: Processado | S3: Processado | U3: 2
A4: 660453584 | B4: 45843 | C4: Sim | D4: 660453584 | G4: Apólice | H4: 129436567 | I4: 0 | J4: 6-Correio Electronico | K4: 7-Outros | L4: Captura de parcela rejeitada - Apólice 129436567 - CAROLINA DUTRA DEGLI ESPOSTI | M4: leonardo@chsseguros.com.br | O4: 57 | P4: 5705 | Q4: Prezado(a), Identificamos uma falha na tentativa de captura da parcela 10 da apólice em questão, para não penalizar o segurado com cobrança de juros, emitimos novo boleto que encontra-se em anexo e dispoível na Ficha Gestão da apólice, por favor encaminhá-lo ao pagador. Caso o cliente já tenha realizado o pagamento, pedimos que desconsidere o boleto ou entre em contato conosco através do gestor de operações na opção "Cobrança Indevida". Pedimos desculpas pelo transtorno causado. Att. Departamento de Cobrança "Este e-mail é um envio automático, favor não responder.” | R4: Processado | S4: Processado | U4: 3
A5: 676932928 | B5: 45843 | C5: Sim | D5: 676932928 | G5: Apólice | H5: 129736941 | I5: 0 | J5: 6-Correio Electronico | K5: 7-Outros | L5: Captura de parcela rejeitada - Apólice 129736941 - ANDRE SOARES TRINDADE | M5: godoycoimbra@hotmail.com | O5: 57 | P5: 5705 | Q5: Prezado(a), Identificamos uma falha na tentativa de captura da parcela 9 da apólice em questão, para não penalizar o segurado com cobrança de juros, emitimos novo boleto que encontra-se em anexo e dispoível na Ficha Gestão da apólice, por favor encaminhá-lo ao pagador. Caso o cliente já tenha realizado o pagamento, pedimos que desconsidere o boleto ou entre em contato conosco através do gestor de operações na opção "Cobrança Indevida". Pedimos desculpas pelo transtorno causado. Att. Departamento de Cobrança "Este e-mail é um envio automático, favor não responder.” | R5: Processado | S5: Processado | U5: 4
A6: 681615807 | B6: 45843 | C6: Sim | D6: 681615807 | G6: Apólice | H6: 129827681 | I6: 0 | J6: 6-Correio Electronico | K6: 7-Outros | L6: Captura de parcela rejeitada - Apólice 129827681 - MARCAL DURVAL SIQUEIRA PAIVA JUNIOR | M6: rpa@teste.com.br | O6: 57 | P6: 5705 | Q6: Prezado(a), Identificamos uma falha na tentativa de captura da parcela 9 da apólice em questão, para não penalizar o segurado com cobrança de juros, emitimos novo boleto que encontra-se em anexo e dispoível na Ficha Gestão da apólice, por favor encaminhá-lo ao pagador. Caso o cliente já tenha realizado o pagamento, pedimos que desconsidere o boleto ou entre em contato conosco através do gestor de operações na opção "Cobrança Indevida". Pedimos desculpas pelo transtorno causado. Att. Departamento de Cobrança "Este e-mail é um envio automático, favor não responder.” | R6: Processado | S6: Processado | U6: 5
A7: 682232990 | B7: 45843 | C7: Sim | D7: 682232990 | G7: Apólice | H7: 129841126 | I7: 0 | J7: 6-Correio Electronico | K7: 7-Outros | L7: Captura de parcela rejeitada - Apólice 129841126 - ERICA VIDOTO CARDOSO DE SA | M7: valdecir@bomjesusseguros.com.br | O7: 57 | P7: 5705 | Q7: Prezado(a), Identificamos uma falha na tentativa de captura da parcela 9 da apólice em questão, para não penalizar o segurado com cobrança de juros, emitimos novo boleto que encontra-se em anexo e dispoível na Ficha Gestão da apólice, por favor encaminhá-lo ao pagador. Caso o cliente já tenha realizado o pagamento, pedimos que desconsidere o boleto ou entre em contato conosco através do gestor de operações na opção "Cobrança Indevida". Pedimos desculpas pelo transtorno causado. Att. Departamento de Cobrança "Este e-mail é um envio automático, favor não responder.” | R7: Processado | S7: Processado | U7: 6
A8: 683806537 | B8: 45843 | C8: Sim | D8: 683806537 | G8: Apólice | H8: 129851756 | I8: 0 | J8: 6-Correio Electronico | K8: 7-Outros | L8: Captura de parcela rejeitada - Apólice 129851756 - RODRIGO PONTIN | M8: barizon@barizoncorretora.com.br | O8: 57 | P8: 5705 | Q8: Prezado(a), Identificamos uma falha na tentativa de captura da parcela 9 da apólice em questão, para não penalizar o segurado com cobrança de juros, emitimos novo boleto que encontra-se em anexo e dispoível na Ficha Gestão da apólice, por favor encaminhá-lo ao pagador. Caso o cliente já tenha realizado o pagamento, pedimos que desconsidere o boleto ou entre em contato conosco através do gestor de operações na opção "Cobrança Indevida". Pedimos desculpas pelo transtorno causado. Att. Departamento de Cobrança "Este e-mail é um envio automático, favor não responder.” | R8: Processado | S8: Processado | U8: 7
A9: 684220449 | B9: 45843 | C9: Sim | D9: 684220449 | G9: Apólice | H9: 129820563 | I9: 0 | J9: 6-Correio Electronico | K9: 7-Outros | L9: Captura de parcela rejeitada - Apólice 129820563 - LUIS ANTONIO DOTTA | M9: pendencias@jlcf.com.br | O9: 57 | P9: 5705 | Q9: Prezado(a), Identificamos uma falha na tentativa de captura da parcela 9 da apólice em questão, para não penalizar o segurado com cobrança de juros, emitimos novo boleto que encontra-se em anexo e dispoível na Ficha Gestão da apólice, por favor encaminhá-lo ao pagador. Caso o cliente já tenha realizado o pagamento, pedimos que desconsidere o boleto ou entre em contato conosco através do gestor de operações na opção "Cobrança Indevida". Pedimos desculpas pelo transtorno causado. Att. Departamento de Cobrança "Este e-mail é um envio automático, favor não responder.” | R9: Processado | S9: Processado | U9: 8
A10: 684368545 | B10: 45843 | C10: Sim | D10: 684368545 | G10: Apólice | H10: 129876036 | I10: 0 | J10: 6-Correio Electronico | K10: 7-Outros | L10: Captura de parcela rejeitada - Apólice 129876036 - TATIANA TEIXEIRA DE ARAUJO | M10: ja@mrgseguros.com.br | O10: 57 | P10: 5705 | Q10: Prezado(a), Identificamos uma falha na tentativa de captura da parcela 9 da apólice em questão, para não penalizar o segurado com cobrança de juros, emitimos novo boleto que encontra-se em anexo e dispoível na Ficha Gestão da apólice, por favor encaminhá-lo ao pagador. Caso o cliente já tenha realizado o pagamento, pedimos que desconsidere o boleto ou entre em contato conosco através do gestor de operações na opção "Cobrança Indevida". Pedimos desculpas pelo transtorno causado. Att. Departamento de Cobrança "Este e-mail é um envio automático, favor não responder.” | R10: Processado | S10: Processado | U10: 9
A11: 684397304 | B11: 45843 | C11: Sim | D11: 684397304 | G11: Apólice | H11: 129854237 | I11: 0 | J11: 6-Correio Electronico | K11: 7-Outros | L11: Captura de parcela rejeitada - Apólice 129854237 - PAMELLA KATRIANNY SOUZA PONTES FIUZA | M11: eloirseguros@hotmail.com | O11: 57 | P11: 5705 | Q11: Prezado(a), Identificamos uma falha na tentativa de captura da parcela 9 da apólice em questão, para não penalizar o segurado com cobrança de juros, emitimos novo boleto que encontra-se em anexo e dispoível na Ficha Gestão da apólice, por favor encaminhá-lo ao pagador. Caso o cliente já tenha realizado o pagamento, pedimos que desconsidere o boleto ou entre em contato conosco através do gestor de operações na opção "Cobrança Indevida". Pedimos desculpas pelo transtorno causado. Att. Departamento de Cobrança "Este e-mail é um envio automático, favor não responder.” | R11: Processado | S11: Processado | U11: 10
A12: 696721327 | B12: 45843 | C12: Sim | D12: 696721327 | G12: Apólice | H12: 130087894 | I12: 0 | J12: 6-Correio Electronico | K12: 7-Outros | L12: Captura de parcela rejeitada - Apólice 130087894 - MARCO ANTONIO DOS SANTOS LACERDA | M12: orlaseguros@orlaseguros.com.br | O12: 57 | P12: 5705 | Q12: Prezado(a), Identificamos uma falha na tentativa de captura da parcela 8 da apólice em questão, para não penalizar o segurado com cobrança de juros, emitimos novo boleto que encontra-se em anexo e dispoível na Ficha Gestão da apólice, por favor encaminhá-lo ao pagador. Caso o cliente já tenha realizado o pagamento, pedimos que desconsidere o boleto ou entre em contato conosco através do gestor de operações na opção "Cobrança Indevida". Pedimos desculpas pelo transtorno causado. Att. Departamento de Cobrança "Este e-mail é um envio automático, favor não responder.” | R12: Processado | S12: Processado | U12: 11
A13: 703042493 | B13: 45843 | C13: Sim | D13: 703042493 | G13: Apólice | H13: 130199774 | I13: 0 | J13: 6-Correio Electronico | K13: 7-Outros | L13: Captura de parcela rejeitada - Apólice 130199774 - MARCIO DE SIQUEIRA E SILVA | M13: valter@hqzcorretora.com.br | O13: 57 | P13: 5705 | Q13: Prezado(a), Identificamos uma falha na tentativa de captura da parcela 8 da apólice em questão, para não penalizar o segurado com cobrança de juros, emitimos novo boleto que encontra-se em anexo e dispoível na Ficha Gestão da apólice, por favor encaminhá-lo ao pagador. Caso o cliente já tenha realizado o pagamento, pedimos que desconsidere o boleto ou entre em contato conosco através do gestor de operações na opção "Cobrança Indevida". Pedimos desculpas pelo transtorno causado. Att. Departamento de Cobrança "Este e-mail é um envio automático, favor não responder.” | R13: Processado | S13: Processado | U13: 12
... A286: 866212586 | B286: 45843 | C286: Sim | D286: 866212586 | G286: Apólice | H286: 130222779 | I286: 0 | J286: 6-Correio Electronico | K286: 7-Outros | L286: Captura de parcela rejeitada - Apólice 130222779 - MATHEUS CIRIBELI | M286: corretoradesegurosjc@yahoo.com | O286: 57 | P286: 5705 | Q286: Prezado(a), Identificamos uma falha na tentativa de captura da parcela . da apólice em questão, para não penalizar o segurado com cobrança de juros, emitimos novo boleto que encontra-se em anexo e dispoível na Ficha Gestão da apólice, por favor encaminhá-lo ao pagador. Caso o cliente já tenha realizado o pagamento, pedimos que desconsidere o boleto ou entre em contato conosco através do gestor de operações na opção "Cobrança Indevida". Pedimos desculpas pelo transtorno causado. Att. Departamento de Cobrança "Este e-mail é um envio automático, favor não responder.” | R286: Processado | S286: Processado | U286: 285

Sheet Enviados
A1: POLIZA | B1: NOTA | C1: TXNOTA | D1: USUARIOENVIO | E1: FEJECUCION
A2: 128922475 | B2: 5705 | C2: Proatividade manual Robô | D2: BE53725 | E2: 45812
A3: 128998967 | B3: 5705 | C3: Proatividade manual Robô | D3: BE53725 | E3: 45812
A4: 129064609 | B4: 5705 | C4: Proatividade manual Robô | D4: BE53725 | E4: 45812
A5: 129134133 | B5: 5705 | C5: Proatividade manual Robô | D5: BE53725 | E5: 45812
A6: 129142868 | B6: 5705 | C6: Proatividade manual Robô | D6: BE53725 | E6: 45812
A7: 129144984 | B7: 5705 | C7: Proatividade manual Robô | D7: BE53725 | E7: 45812
A8: 129145543 | B8: 5705 | C8: Proatividade manual Robô | D8: BE53725 | E8: 45812
A9: 129148480 | B9: 5705 | C9: Proatividade manual Robô | D9: BE53725 | E9: 45812
A10: 129154680 | B10: 5705 | C10: Proatividade manual Robô | D10: BE53725 | E10: 45812
A11: 129160105 | B11: 5705 | C11: Proatividade manual Robô | D11: BE53725 | E11: 45812
A12: 129364094 | B12: 5705 | C12: Proatividade manual Robô | D12: BE53725 | E12: 45812
A13: 129441284 | B13: 5705 | C13: Proatividade manual Robô | D13: BE53725 | E13: 45812
... A98: 132382372 | B98: 5705 | C98: Proatividade manual Robô | D98: BE53725 | E98: 45812

Sheet Não enviados
A1: Apólice | B1: Recibos | C1: Não enviados | D1: Motivo | E1: Ação
A2: 129134133 | B2: =_xlfn.XLOOKUP(A2,Planilha1!H:H,Planilha1!D:D) -> #N/A
A3: 129160105 | B3: =_xlfn.XLOOKUP(A3,Planilha1!H:H,Planilha1!D:D) -> #N/A
A4: 129148480 | B4: =_xlfn.XLOOKUP(A4,Planilha1!H:H,Planilha1!D:D) -> #N/A
A5: 129145543 | B5: =_xlfn.XLOOKUP(A5,Planilha1!H:H,Planilha1!D:D) -> #N/A
A6: 128998967 | B6: =_xlfn.XLOOKUP(A6,Planilha1!H:H,Planilha1!D:D) -> #N/A
A7: 129441284 | B7: =_xlfn.XLOOKUP(A7,Planilha1!H:H,Planilha1!D:D) -> #N/A
A8: 129599207 | B8: =_xlfn.XLOOKUP(A8,Planilha1!H:H,Planilha1!D:D) -> #N/A
A9: 129834862 | B9: =_xlfn.XLOOKUP(A9,Planilha1!H:H,Planilha1!D:D) -> #N/A | C9: #N/A | D9: Cobrado
A10: 129998580 | B10: =_xlfn.XLOOKUP(A10,Planilha1!H:H,Planilha1!D:D) -> #N/A
A11: 130011908 | B11: =_xlfn.XLOOKUP(A11,Planilha1!H:H,Planilha1!D:D) -> #N/A
A12: 130021579 | B12: =_xlfn.XLOOKUP(A12,Planilha1!H:H,Planilha1!D:D) -> #N/A
A13: 130026730 | B13: =_xlfn.XLOOKUP(A13,Planilha1!H:H,Planilha1!D:D) -> #N/A
A14: 130394687 | B14: =_xlfn.XLOOKUP(A14,Planilha1!H:H,Planilha1!D:D) -> #N/A
A15: 130381891 | B15: =_xlfn.XLOOKUP(A15,Planilha1!H:H,Planilha1!D:D) -> #N/A
A16: 130424524 | B16: =_xlfn.XLOOKUP(A16,Planilha1!H:H,Planilha1!D:D) -> #N/A
A17: 130434836 | B17: =_xlfn.XLOOKUP(A17,Planilha1!H:H,Planilha1!D:D) -> #N/A
A18: 130410391 | B18: =_xlfn.XLOOKUP(A18,Planilha1!H:H,Planilha1!D:D) -> #N/A
A19: 130405533 | B19: =_xlfn.XLOOKUP(A19,Planilha1!H:H,Planilha1!D:D) -> #N/A
A20: 130782231 | B20: =_xlfn.XLOOKUP(A20,Planilha1!H:H,Planilha1!D:D) -> #N/A
A21: 130781514 | B21: =_xlfn.XLOOKUP(A21,Planilha1!H:H,Planilha1!D:D) -> #N/A
... A42: 128922475 | B42: =_xlfn.XLOOKUP(A42,Planilha1!H:H,Planilha1!D:D) -> #N/A
A43: 129012469 | B43: =_xlfn.XLOOKUP(A43,Planilha1!H:H,Planilha1!D:D) -> #N/A | C43: #N/A | D43: Cobrado
A44: 129142868 | B44: =_xlfn.XLOOKUP(A44,Planilha1!H:H,Planilha1!D:D) -> #N/A
A45: 129144984 | B45: =_xlfn.XLOOKUP(A45,Planilha1!H:H,Planilha1!D:D) -> #N/A
A46: 129154680 | B46: =_xlfn.XLOOKUP(A46,Planilha1!H:H,Planilha1!D:D) -> #N/A
A47: 129116738 | B47: =_xlfn.XLOOKUP(A47,Planilha1!H:H,Planilha1!D:D) -> #N/A | C47: #N/A | D47: Cobrado
A48: 129351255 | B48: =_xlfn.XLOOKUP(A48,Planilha1!H:H,Planilha1!D:D) -> #N/A | C48: #N/A | D48: Cobrado
A49: 129548423 | B49: =_xlfn.XLOOKUP(A49,Planilha1!H:H,Planilha1!D:D) -> #N/A
A50: 129568043 | B50: =_xlfn.XLOOKUP(A50,Planilha1!H:H,Planilha1!D:D) -> #N/A
A51: 129557568 | B51: =_xlfn.XLOOKUP(A51,Planilha1!H:H,Planilha1!D:D) -> #N/A
A52: 129599644 | B52: =_xlfn.XLOOKUP(A52,Planilha1!H:H,Planilha1!D:D) -> #N/A | C52: #N/A | D52: Cobrado
A53: 129536777 | B53: =_xlfn.XLOOKUP(A53,Planilha1!H:H,Planilha1!D:D) -> #N/A | C53: #N/A | D53: Cobrado
A54: 130033175 | B54: =_xlfn.XLOOKUP(A54,Planilha1!H:H,Planilha1!D:D) -> #N/A
A55: 130033353 | B55: =_xlfn.XLOOKUP(A55,Planilha1!H:H,Planilha1!D:D) -> #N/A
A56: 130030251 | B56: =_xlfn.XLOOKUP(A56,Planilha1!H:H,Planilha1!D:D) -> #N/A
A57: 130029976 | B57: =_xlfn.XLOOKUP(A57,Planilha1!H:H,Planilha1!D:D) -> #N/A
A58: 130029349 | B58: =_xlfn.XLOOKUP(A58,Planilha1!H:H,Planilha1!D:D) -> #N/A
A59: 130016037 | B59: =_xlfn.XLOOKUP(A59,Planilha1!H:H,Planilha1!D:D) -> #N/A
A60: 130388789 | B60: =_xlfn.XLOOKUP(A60,Planilha1!H:H,Planilha1!D:D) -> #N/A | C60: #N/A | D60: Cobrado
...
