Workbook

Sheet Planilha1
A1: Nº recibo | B1: Limite máximo | C1: sem juros/com juros | D1: NomeArquivo | E1: status | F1: Mensagem | G1: TipoReferencia | H1: NumeroReferencia | I1: Aplica | J1: Meio de Envio | K1: Tipo Destino | L1: Nome | M1: E-mail Destino | N1: E-mail Copia | O1: ModeloDescricao | P1: ModeloDescricao2 | Q1: Aviso | R1: status | S1: Upload | T1: ERRO | U1: linha
A2: 666761758 | B2: 45859 | C2: Sim | D2: 666761758 | G2: Apólice | H2: 129558670 | I2: 0 | J2: 6-Correio Electronico | K2: 7-Outros | L2: Captura de parcela rejeitada - Apólice 129558670 - ALESSANDRA VIRGILIO DE SOUSA | M2: milanaevanderseguros@gmail.com | O2: 57 | P2: 5705 | Q2: Prezado(a), Identificamos uma falha na tentativa de captura da parcela 10 da apólice em questão, para não penalizar o segurado com cobrança de juros, emitimos novo boleto que encontra-se em anexo e dispoível na Ficha Gestão da apólice, por favor encaminhá-lo ao pagador. Caso o cliente já tenha realizado o pagamento, pedimos que desconsidere o boleto ou entre em contato conosco através do gestor de operações na opção "Cobrança Indevida". Pedimos desculpas pelo transtorno causado. Att. Departamento de Cobrança "Este e-mail é um envio automático, favor não responder.” | R2: Processado | S2: Processado | U2: 1
A3: 668875259 | B3: 45859 | C3: Sim | D3: 668875259 | G3: Apólice | H3: 129598995 | I3: 0 | J3: 6-Correio Electronico | K3: 7-Outros | L3: Captura de parcela rejeitada - Apólice 129598995 - ROBERTA REINIGER OLIVERO | M3: raphaela@hmseguros.com.br | O3: 57 | P3: 5705 | Q3: Prezado(a), Identificamos uma falha na tentativa de captura da parcela 10 da apólice em questão, para não penalizar o segurado com cobrança de juros, emitimos novo boleto que encontra-se em anexo e dispoível na Ficha Gestão da apólice, por favor encaminhá-lo ao pagador. Caso o cliente já tenha realizado o pagamento, pedimos que desconsidere o boleto ou entre em contato conosco através do gestor de operações na opção "Cobrança Indevida". Pedimos desculpas pelo transtorno causado. Att. Departamento de Cobrança "Este e-mail é um envio automático, favor não responder.” | R3: Processado | S3: Processado | U3: 2
A4: 670372162 | B4: 45859 | C4: Sim | D4: 670372162 | G4: Apólice | H4: 129624074 | I4: 0 | J4: 6-Correio Electronico | K4: 7-Outros | L4: Captura de parcela rejeitada - Apólice 129624074 - ROSELAINE BONFIM LIMA SILVA | M4: blindage@blindageseguros.com.br | O4: 57 | P4: 5705 | Q4: Prezado(a), Identificamos uma falha na tentativa de captura da parcela 10 da apólice em questão, para não penalizar o segurado com cobrança de juros, emitimos novo boleto que encontra-se em anexo e dispoível na Ficha Gestão da apólice, por favor encaminhá-lo ao pagador. Caso o cliente já tenha realizado o pagamento, pedimos que desconsidere o boleto ou entre em contato conosco através do gestor de operações na opção "Cobrança Indevida". Pedimos desculpas pelo transtorno causado. Att. Departamento de Cobrança "Este e-mail é um envio automático, favor não responder.” | R4: Processado | S4: Processado | U4: 3
A5: 672719105 | B5: 45859 | C5: Sim | D5: 672719105 | G5: Apólice | H5: 129663894 | I5: 0 | J5: 6-Correio Electronico | K5: 7-Outros | L5: Captura de parcela rejeitada - Apólice 129663894 - LUIZ CARLOS MUNHOZ | M5: reesp@astecaseguros.com.br | O5: 57 | P5: 5705 | Q5: Prezado(a), Identificamos uma falha na tentativa de captura da parcela 10 da apólice em questão, para não penalizar o segurado com cobrança de juros, emitimos novo boleto que encontra-se em anexo e dispoível na Ficha Gestão da apólice, por favor encaminhá-lo ao pagador. Caso o cliente já tenha realizado o pagamento, pedimos que desconsidere o boleto ou entre em contato conosco através do gestor de operações na opção "Cobrança Indevida". Pedimos desculpas pelo transtorno causado. Att. Departamento de Cobrança "Este e-mail é um envio automático, favor não responder.” | R5: Processado | S5: Processado | U5: 4
A6: 672742867 | B6: 45859 | C6: Sim | D6: 672742867 | G6: Apólice | H6: 129662685 | I6: 0 | J6: 6-Correio Electronico | K6: 7-Outros | L6: Captura de parcela rejeitada - Apólice 129662685 - JOSE HELENO DE SOUZA | M6: coperseg.pe@terra.com.br | O6: 57 | P6: 5705 | Q6: Prezado(a), Identificamos uma falha na tentativa de captura da parcela 10 da apólice em questão, para não penalizar o segurado com cobrança de juros, emitimos novo boleto que encontra-se em anexo e dispoível na Ficha Gestão da apólice, por favor encaminhá-lo ao pagador. Caso o cliente já tenha realizado o pagamento, pedimos que desconsidere o boleto ou entre em contato conosco através do gestor de operações na opção "Cobrança Indevida". Pedimos desculpas pelo transtorno causado. Att. Departamento de Cobrança "Este e-mail é um envio automático, favor não responder.” | R6: Processado | S6: Processado | U6: 5
A7: 672922568 | B7: 45859 | C7: Sim | D7: 672922568 | G7: Apólice | H7: 129656383 | I7: 0 | J7: 6-Correio Electronico | K7: 7-Outros | L7: Captura de parcela rejeitada - Apólice 129656383 - SABRINA DE OLIVEIRA FLORENCIO | M7: renovacaoseguros@honda.com.br | O7: 57 | P7: 5705 | Q7: Prezado(a), Identificamos uma falha na tentativa de captura da parcela 10 da apólice em questão, para não penalizar o segurado com cobrança de juros, emitimos novo boleto que encontra-se em anexo e dispoível na Ficha Gestão da apólice, por favor encaminhá-lo ao pagador. Caso o cliente já tenha realizado o pagamento, pedimos que desconsidere o boleto ou entre em contato conosco através do gestor de operações na opção "Cobrança Indevida". Pedimos desculpas pelo transtorno causado. Att. Departamento de Cobrança "Este e-mail é um envio automático, favor não responder.” | R7: Processado | S7: Processado | U7: 6
A8: 673397208 | B8: 45859 | C8: Sim | D8: 673397208 | G8: Apólice | H8: 129678576 | I8: 0 | J8: 6-Correio Electronico | K8: 7-Outros | L8: Captura de parcela rejeitada - Apólice 129678576 - PEDRO RAFAEL DE OLIVEIRA PORTO | M8: corretora@pessego.com | O8: 57 | P8: 5705 | Q8: Prezado(a), Identificamos uma falha na tentativa de captura da parcela 10 da apólice em questão, para não penalizar o segurado com cobrança de juros, emitimos novo boleto que encontra-se em anexo e dispoível na Ficha Gestão da apólice, por favor encaminhá-lo ao pagador. Caso o cliente já tenha realizado o pagamento, pedimos que desconsidere o boleto ou entre em contato conosco através do gestor de operações na opção "Cobrança Indevida". Pedimos desculpas pelo transtorno causado. Att. Departamento de Cobrança "Este e-mail é um envio automático, favor não responder.” | R8: Processado | S8: Processado | U8: 7
A9: 673484261 | B9: 45859 | C9: Sim | D9: 673484261 | G9: Apólice | H9: 129662090 | I9: 0 | J9: 6-Correio Electronico | K9: 7-Outros | L9: Captura de parcela rejeitada - Apólice 129662090 - ELIANA ANDREAZZI | M9: balta@baltaseguros.com.br | O9: 57 | P9: 5705 | Q9: Prezado(a), Identificamos uma falha na tentativa de captura da parcela 10 da apólice em questão, para não penalizar o segurado com cobrança de juros, emitimos novo boleto que encontra-se em anexo e dispoível na Ficha Gestão da apólice, por favor encaminhá-lo ao pagador. Caso o cliente já tenha realizado o pagamento, pedimos que desconsidere o boleto ou entre em contato conosco através do gestor de operações na opção "Cobrança Indevida". Pedimos desculpas pelo transtorno causado. Att. Departamento de Cobrança "Este e-mail é um envio automático, favor não responder.” | R9: Processado | S9: Processado | U9: 8
A10: 694995949 | B10: 45859 | C10: Sim | D10: 694995949 | G10: Apólice | H10: 130038760 | I10: 0 | J10: 6-Correio Electronico | K10: 7-Outros | L10: Captura de parcela rejeitada - Apólice 130038760 - LILIAN GALLINELLA CRUZ | M10: mmfigueiredocorretora@outlook.com | O10: 57 | P10: 5705 | Q10: Prezado(a), Identificamos uma falha na tentativa de captura da parcela 9 da apólice em questão, para não penalizar o segurado com cobrança de juros, emitimos novo boleto que encontra-se em anexo e dispoível na Ficha Gestão da apólice, por favor encaminhá-lo ao pagador. Caso o cliente já tenha realizado o pagamento, pedimos que desconsidere o boleto ou entre em contato conosco através do gestor de operações na opção "Cobrança Indevida". Pedimos desculpas pelo transtorno causado. Att. Departamento de Cobrança "Este e-mail é um envio automático, favor não responder.” | R10: Processado | S10: Processado | U10: 9
A11: 695273957 | B11: 45859 | C11: Sim | D11: 695273957 | G11: Apólice | H11: 130066339 | I11: 0 | J11: 6-Correio Electronico | K11: 7-Outros | L11: Captura de parcela rejeitada - Apólice 130066339 - THAMARA LUIZA OLIVEIRA LEMOS | M11: allianz@redelojacorr.com.br | O11: 57 | P11: 5705 | Q11: Prezado(a), Identificamos uma falha na tentativa de captura da parcela 9 da apólice em questão, para não penalizar o segurado com cobrança de juros, emitimos novo boleto que encontra-se em anexo e dispoível na Ficha Gestão da apólice, por favor encaminhá-lo ao pagador. Caso o cliente já tenha realizado o pagamento, pedimos que desconsidere o boleto ou entre em contato conosco através do gestor de operações na opção "Cobrança Indevida". Pedimos desculpas pelo transtorno causado. Att. Departamento de Cobrança "Este e-mail é um envio automático, favor não responder.” | R11: Processado | S11: Processado | U11: 10
A12: 695386882 | B12: 45859 | C12: Sim | D12: 695386882 | G12: Apólice | H12: 130069374 | I12: 0 | J12: 6-Correio Electronico | K12: 7-Outros | L12: Captura de parcela rejeitada - Apólice 130069374 - ANGELINA BOCHI SALLES | M12: contato@nixseguros.com.br | O12: 57 | P12: 5705 | Q12: Prezado(a), Identificamos uma falha na tentativa de captura da parcela 9 da apólice em questão, para não penalizar o segurado com cobrança de juros, emitimos novo boleto que encontra-se em anexo e dispoível na Ficha Gestão da apólice, por favor encaminhá-lo ao pagador. Caso o cliente já tenha realizado o pagamento, pedimos que desconsidere o boleto ou entre em contato conosco através do gestor de operações na opção "Cobrança Indevida". Pedimos desculpas pelo transtorno causado. Att. Departamento de Cobrança "Este e-mail é um envio automático, favor não responder.” | R12: Processado | S12: Processado | U12: 11
A13: 695813620 | B13: 45859 | C13: Sim | D13: 695813620 | G13: Apólice | H13: 130063826 | I13: 0 | J13: 6-Correio Electronico | K13: 7-Outros | L13: Captura de parcela rejeitada - Apólice 130063826 - MARCIO BAPTISTA DA CRUZ | M13: vitor@gropelo.com.br | O13: 57 | P13: 5705 | Q13: Prezado(a), Identificamos uma falha na tentativa de captura da parcela 9 da apólice em questão, para não penalizar o segurado com cobrança de juros, emitimos novo boleto que encontra-se em anexo e dispoível na Ficha Gestão da apólice, por favor encaminhá-lo ao pagador. Caso o cliente já tenha realizado o pagamento, pedimos que desconsidere o boleto ou entre em contato conosco através do gestor de operações na opção "Cobrança Indevida". Pedimos desculpas pelo transtorno causado. Att. Departamento de Cobrança "Este e-mail é um envio automático, favor não responder.” | R13: Processado | S13: Processado | U13: 12
... A120: 803933179 | B120: 45859 | C120: Sim | D120: 803933179 | G120: Apólice | H120: 131936767 | I120: 0 | J120: 6-Correio Electronico | K120: 7-Outros | L120: Captura de parcela rejeitada - Apólice 131936767 - FERNANDA ROCHA GOMES | M120: segurosresendecoimbra@gmail.com | O120: 57 | P120: 5705 | Q120: Prezado(a), Identificamos uma falha na tentativa de captura da parcela 4 da apólice em questão, para não penalizar o segurado com cobrança de juros, emitimos novo boleto que encontra-se em anexo e dispoível na Ficha Gestão da apólice, por favor encaminhá-lo ao pagador. Caso o cliente já tenha realizado o pagamento, pedimos que desconsidere o boleto ou entre em contato conosco através do gestor de operações na opção "Cobrança Indevida". Pedimos desculpas pelo transtorno causado. Att. Departamento de Cobrança "Este e-mail é um envio automático, favor não responder.” | R120: Processado | S120: Processado | U120: 119
A121: 664860818 | B121: 45859 | C121: Sim | D121: 664860818 | G121: Apólice | H121: 129508487 | I121: 0 | J121: 6-Correio Electronico | K121: 7-Outros | L121: =CONCATENATE("Captura de parcela rejeitada - Apólice ",E121," - ",K121) -> Captura de parcela rejeitada - Apólice - 7-Outros | M121: fernando@gaveaseguros.com.br | O121: 57 | P121: 5705 | Q121: =[1]TEXTO!$A$1&[1]Rejeição!L121&[1]TEXTO!$B$1 -> Prezado(a), Identificamos uma falha na tentativa de captura da parcela da apólice em questão, para não penalizar o segurado com cobrança de juros, emitimos novo boleto que encontra-se em anexo e dispoível na Ficha Gestão da apólice, por favor encaminhá-lo ao pagador. Caso o cliente já tenha realizado o pagamento, pedimos que desconsidere o boleto ou entre em contato conosco através do gestor de operações na opção "Cobrança Indevida". Pedimos desculpas pelo transtorno causado. Att. Departamento de Cobrança "Este e-mail é um envio automático, favor não responder.” | R121: Processado | S121: Processado | U121: 120
A122: 666434935 | B122: 45859 | C122: Sim | D122: 666434935 | G122: Apólice | H122: 129552015 | I122: 0 | J122: 6-Correio Electronico | K122: 7-Outros | L122: =CONCATENATE("Captura de parcela rejeitada - Apólice ",E122," - ",K122) -> Captura de parcela rejeitada - Apólice - 7-Outros | M122: corrente@correntecorretora.com.br | O122: 57 | P122: 5705 | Q122: =[1]TEXTO!$A$1&[1]Rejeição!L122&[1]TEXTO!$B$1 -> Prezado(a), Identificamos uma falha na tentativa de captura da parcela da apólice em questão, para não penalizar o segurado com cobrança de juros, emitimos novo boleto que encontra-se em anexo e dispoível na Ficha Gestão da apólice, por favor encaminhá-lo ao pagador. Caso o cliente já tenha realizado o pagamento, pedimos que desconsidere o boleto ou entre em contato conosco através do gestor de operações na opção "Cobrança Indevida". Pedimos desculpas pelo transtorno causado. Att. Departamento de Cobrança "Este e-mail é um envio automático, favor não responder.” | R122: Processado | S122: Processado | U122: 121
A123: 670371206 | B123: 45859 | C123: Sim | D123: 670371206 | G123: Apólice | H123: 129624102 | I123: 0 | J123: 6-Correio Electronico | K123: 7-Outros | L123: =CONCATENATE("Captura de parcela rejeitada - Apólice ",E123," - ",K123) -> Captura de parcela rejeitada - Apólice - 7-Outros | M123: topseguros@topseguros.com.br | O123: 57 | P123: 5705 | Q123: =[1]TEXTO!$A$1&[1]Rejeição!L123&[1]TEXTO!$B$1 -> Prezado(a), Identificamos uma falha na tentativa de captura da parcela da apólice em questão, para não penalizar o segurado com cobrança de juros, emitimos novo boleto que encontra-se em anexo e dispoível na Ficha Gestão da apólice, por favor encaminhá-lo ao pagador. Caso o cliente já tenha realizado o pagamento, pedimos que desconsidere o boleto ou entre em contato conosco através do gestor de operações na opção "Cobrança Indevida". Pedimos desculpas pelo transtorno causado. Att. Departamento de Cobrança "Este e-mail é um envio automático, favor não responder.” | R123: Processado | S123: Processado | U123: 122
A124: 670426083 | B124: 45859 | C124: Sim | D124: 670426083 | G124: Apólice | H124: 129624949 | I124: 0 | J124: 6-Correio Electronico | K124: 7-Outros | L124: =CONCATENATE("Captura de parcela rejeitada - Apólice ",E124," - ",K124) -> Captura de parcela rejeitada - Apólice - 7-Outros | M124: comercial@maresseguros.com.br | O124: 57 | P124: 5705 | Q124: =[1]TEXTO!$A$1&[1]Rejeição!L124&[1]TEXTO!$B$1 -> Prezado(a), Identificamos uma falha na tentativa de captura da parcela da apólice em questão, para não penalizar o segurado com cobrança de juros, emitimos novo boleto que encontra-se em anexo e dispoível na Ficha Gestão da apólice, por favor encaminhá-lo ao pagador. Caso o cliente já tenha realizado o pagamento, pedimos que desconsidere o boleto ou entre em contato conosco através do gestor de operações na opção "Cobrança Indevida". Pedimos desculpas pelo transtorno causado. Att. Departamento de Cobrança "Este e-mail é um envio automático, favor não responder.” | R124: Processado | S124: Processado | U124: 123
A125: 671123705 | B125: 45859 | C125: Sim | D125: 671123705 | G125: Apólice | H125: 129638917 | I125: 0 | J125: 6-Correio Electronico | K125: 7-Outros | L125: =CONCATENATE("Captura de parcela rejeitada - Apólice ",E125," - ",K125) -> Captura de parcela rejeitada - Apólice - 7-Outros | M125: rodrigo@bankseguros.com.br | O125: 57 | P125: 5705 | Q125: =[1]TEXTO!$A$1&[1]Rejeição!L125&[1]TEXTO!$B$1 -> Prezado(a), Identificamos uma falha na tentativa de captura da parcela da apólice em questão, para não penalizar o segurado com cobrança de juros, emitimos novo boleto que encontra-se em anexo e dispoível na Ficha Gestão da apólice, por favor encaminhá-lo ao pagador. Caso o cliente já tenha realizado o pagamento, pedimos que desconsidere o boleto ou entre em contato conosco através do gestor de operações na opção "Cobrança Indevida". Pedimos desculpas pelo transtorno causado. Att. Departamento de Cobrança "Este e-mail é um envio automático, favor não responder.” | R125: Processado | S125: Processado | U125: 124
A126: 671675019 | B126: 45859 | C126: Sim | D126: 671675019 | G126: Apólice | H126: 129627404 | I126: 0 | J126: 6-Correio Electronico | K126: 7-Outros | L126: =CONCATENATE("Captura de parcela rejeitada - Apólice ",E126," - ",K126) -> Captura de parcela rejeitada - Apólice - 7-Outros | M126: dariobarreto@dbcorretora.com.br | O126: 57 | P126: 5705 | Q126: =[1]TEXTO!$A$1&[1]Rejeição!L126&[1]TEXTO!$B$1 -> Prezado(a), Identificamos uma falha na tentativa de captura da parcela da apólice em questão, para não penalizar o segurado com cobrança de juros, emitimos novo boleto que encontra-se em anexo e dispoível na Ficha Gestão da apólice, por favor encaminhá-lo ao pagador. Caso o cliente já tenha realizado o pagamento, pedimos que desconsidere o boleto ou entre em contato conosco através do gestor de operações na opção "Cobrança Indevida". Pedimos desculpas pelo transtorno causado. Att. Departamento de Cobrança "Este e-mail é um envio automático, favor não responder.” | R126: Processado | S126: Processado | U126: 125
A127: 687717367 | B127: 45859 | C127: Sim | D127: 687717367 | G127: Apólice | H127: 129902522 | I127: 0 | J127: 6-Correio Electronico | K127: 7-Outros | L127: =CONCATENATE("Captura de parcela rejeitada - Apólice ",E127," - ",K127) -> Captura de parcela rejeitada - Apólice - 7-Outros | M127: contato@valdireneramoscorretora.com.br | O127: 57 | P127: 5705 | Q127: =[1]TEXTO!$A$1&[1]Rejeição!L127&[1]TEXTO!$B$1 -> Prezado(a), Identificamos uma falha na tentativa de captura da parcela da apólice em questão, para não penalizar o segurado com cobrança de juros, emitimos novo boleto que encontra-se em anexo e dispoível na Ficha Gestão da apólice, por favor encaminhá-lo ao pagador. Caso o cliente já tenha realizado o pagamento, pedimos que desconsidere o boleto ou entre em contato conosco através do gestor de operações na opção "Cobrança Indevida". Pedimos desculpas pelo transtorno causado. Att. Departamento de Cobrança "Este e-mail é um envio automático, favor não responder.” | R127: Processado | S127: Processado | U127: 126
A128: 693516530 | B128: 45859 | C128: Sim | D128: 693516530 | G128: Apólice | H128: 130026437 | I128: 0 | J128: 6-Correio Electronico | K128: 7-Outros | L128: =CONCATENATE("Captura de parcela rejeitada - Apólice ",E128," - ",K128) -> Captura de parcela rejeitada - Apólice - 7-Outros | M128: seguros@htscorretora.com.br | O128: 57 | P128: 5705 | Q128: =[1]TEXTO!$A$1&[1]Rejeição!L128&[1]TEXTO!$B$1 -> Prezado(a), Identificamos uma falha na tentativa de captura da parcela da apólice em questão, para não penalizar o segurado com cobrança de juros, emitimos novo boleto que encontra-se em anexo e dispoível na Ficha Gestão da apólice, por favor encaminhá-lo ao pagador. Caso o cliente já tenha realizado o pagamento, pedimos que desconsidere o boleto ou entre em contato conosco através do gestor de operações na opção "Cobrança Indevida". Pedimos desculpas pelo transtorno causado. Att. Departamento de Cobrança "Este e-mail é um envio automático, favor não responder.” | R128: Processado | S128: Processado | U128: 127
A129: 694822473 | B129: 45859 | C129: Sim | D129: 694822473 | G129: Apólice | H129: 130058503 | I129: 0 | J129: 6-Correio Electronico | K129: 7-Outros | L129: =CONCATENATE("Captura de parcela rejeitada - Apólice ",E129," - ",K129) -> Captura de parcela rejeitada - Apólice - 7-Outros | M129: norteemissao@nortecorretora.com.br | O129: 57 | P129: 5705 | Q129: =[1]TEXTO!$A$1&[1]Rejeição!L129&[1]TEXTO!$B$1 -> Prezado(a), Identificamos uma falha na tentativa de captura da parcela da apólice em questão, para não penalizar o segurado com cobrança de juros, emitimos novo boleto que encontra-se em anexo e dispoível na Ficha Gestão da apólice, por favor encaminhá-lo ao pagador. Caso o cliente já tenha realizado o pagamento, pedimos que desconsidere o boleto ou entre em contato conosco através do gestor de operações na opção "Cobrança Indevida". Pedimos desculpas pelo transtorno causado. Att. Departamento de Cobrança "Este e-mail é um envio automático, favor não responder.” | R129: Processado | S129: Processado | U129: 128
A130: 695744916 | B130: 45859 | C130: Sim | D130: 695744916 | G130: Apólice | H130: 130074358 | I130: 0 | J130: 6-Correio Electronico | K130: 7-Outros | L130: =CONCATENATE("Captura de parcela rejeitada - Apólice ",E130," - ",K130) -> Captura de parcela rejeitada - Apólice - 7-Outros | M130: claudia.pascon@eplseguros.com.br | O130: 57 | P130: 5705 | Q130: =[1]TEXTO!$A$1&[1]Rejeição!L130&[1]TEXTO!$B$1 -> Prezado(a), Identificamos uma falha na tentativa de captura da parcela da apólice em questão, para não penalizar o segurado com cobrança de juros, emitimos novo boleto que encontra-se em anexo e dispoível na Ficha Gestão da apólice, por favor encaminhá-lo ao pagador. Caso o cliente já tenha realizado o pagamento, pedimos que desconsidere o boleto ou entre em contato conosco através do gestor de operações na opção "Cobrança Indevida". Pedimos desculpas pelo transtorno causado. Att. Departamento de Cobrança "Este e-mail é um envio automático, favor não responder.” | R130: Processado | S130: Processado | U130: 129
A131: 695852867 | B131: 45859 | C131: Sim | D131: 695852867 | G131: Apólice | H131: 130075687 | I131: 0 | J131: 6-Correio Electronico | K131: 7-Outros | L131: =CONCATENATE("Captura de parcela rejeitada - Apólice ",E131," - ",K131) -> Captura de parcela rejeitada - Apólice - 7-Outros | M131: carolina@norcor.com.br | O131: 57 | P131: 5705 | Q131: =[1]TEXTO!$A$1&[1]Rejeição!L131&[1]TEXTO!$B$1 -> Prezado(a), Identificamos uma falha na tentativa de captura da parcela da apólice em questão, para não penalizar o segurado com cobrança de juros, emitimos novo boleto que encontra-se em anexo e dispoível na Ficha Gestão da apólice, por favor encaminhá-lo ao pagador. Caso o cliente já tenha realizado o pagamento, pedimos que desconsidere o boleto ou entre em contato conosco através do gestor de operações na opção "Cobrança Indevida". Pedimos desculpas pelo transtorno causado. Att. Departamento de Cobrança "Este e-mail é um envio automático, favor não responder.” | R131: Processado | S131: Processado | U131: 130
A132: 695886287 | B132: 45859 | C132: Sim | D132: 695886287 | G132: Apólice | H132: 130077067 | I132: 0 | J132: 6-Correio Electronico | K132: 7-Outros | L132: =CONCATENATE("Captura de parcela rejeitada - Apólice ",E132," - ",K132) -> Captura de parcela rejeitada - Apólice - 7-Outros | M132: 3c@seguros3c.com.br | O132: 57 | P132: 5705 | Q132: =[1]TEXTO!$A$1&[1]Rejeição!L132&[1]TEXTO!$B$1 -> Prezado(a), Identificamos uma falha na tentativa de captura da parcela da apólice em questão, para não penalizar o segurado com cobrança de juros, emitimos novo boleto que encontra-se em anexo e dispoível na Ficha Gestão da apólice, por favor encaminhá-lo ao pagador. Caso o cliente já tenha realizado o pagamento, pedimos que desconsidere o boleto ou entre em contato conosco através do gestor de operações na opção "Cobrança Indevida". Pedimos desculpas pelo transtorno causado. Att. Departamento de Cobrança "Este e-mail é um envio automático, favor não responder.” | R132: Processado | S132: Processado | U132: 131
... A268: 779688997 | B268: 45859 | C268: Sim | D268: 779688997 | G268: Apólice | H268: 131540077 | I268: 0 | J268: 6-Correio Electronico | K268: 7-Outros | L268: =CONCATENATE("Captura de parcela rejeitada - Apólice ",E268," - ",K268) -> Captura de parcela rejeitada - Apólice - 7-Outros | M268: godivaseguros@gmail.com | O268: 57 | P268: 5705 | Q268: =[1]TEXTO!$A$1&[1]Rejeição!L268&[1]TEXTO!$B$1 -> Prezado(a), Identificamos uma falha na tentativa de captura da parcela da apólice em questão, para não penalizar o segurado com cobrança de juros, emitimos novo boleto que encontra-se em anexo e dispoível na Ficha Gestão da apólice, por favor encaminhá-lo ao pagador. Caso o cliente já tenha realizado o pagamento, pedimos que desconsidere o boleto ou entre em contato conosco através do gestor de operações na opção "Cobrança Indevida". Pedimos desculpas pelo transtorno causado. Att. Departamento de Cobrança "Este e-mail é um envio automático, favor não responder.” | R268: Processado | S268: Processado | U268: 267

Sheet Enviados
A1: POLIZA | B1: NOTA | C1: TXNOTA | D1: USUARIOENVIO | E1: FEJECUCION
A2: 128922475 | B2: 5705 | C2: Proatividade manual Robô | D2: BE53725 | E2: 45812
A3: 128998967 | B3: 5705 | C3: Proatividade manual Robô | D3: BE53725 | E3: 45812
A4: 129064609 | B4: 5705 | C4: Proatividade manual Robô | D4: BE53725 | E4: 45812
A5: 129134133 | B5: 5705 | C5: Proatividade manual Robô | D5: BE53725 | E5: 45812
A6: 129142868 | B6: 5705 | C6: Proatividade manual Robô | D6: BE53725 | E6: 45812
A7: 129144984 | B7: 5705 | C7: Proatividade manual Robô | D7: BE53725 | E7: 45812
A8: 129145543 | B8: 5705 | C8: Proatividade manual Robô | D8: BE53725 | E8: 45812
A9: 129148480 | B9: 5705 | C9: Proatividade manual Robô | D9: BE53725 | E9: 45812
A10: 129154680 | B10: 5705 | C10: Proatividade manual Robô | D10: BE53725 | E10: 45812
A11: 129160105 | B11: 5705 | C11: Proatividade manual Robô | D11: BE53725 | E11: 45812
A12: 129364094 | B12: 5705 | C12: Proatividade manual Robô | D12: BE53725 | E12: 45812
A13: 129441284 | B13: 5705 | C13: Proatividade manual Robô | D13: BE53725 | E13: 45812
... A98: 132382372 | B98: 5705 | C98: Proatividade manual Robô | D98: BE53725 | E98: 45812

Sheet Não enviados
A1: Apólice | B1: Recibos | C1: Não enviados | D1: Motivo | E1: Ação
A2: 129134133 | B2: =_xlfn.XLOOKUP(A2,Planilha1!H:H,Planilha1!D:D) -> #N/A
A3: 129160105 | B3: =_xlfn.XLOOKUP(A3,Planilha1!H:H,Planilha1!D:D) -> #N/A
A4: 129148480 | B4: =_xlfn.XLOOKUP(A4,Planilha1!H:H,Planilha1!D:D) -> #N/A
A5: 129145543 | B5: =_xlfn.XLOOKUP(A5,Planilha1!H:H,Planilha1!D:D) -> #N/A
A6: 128998967 | B6: =_xlfn.XLOOKUP(A6,Planilha1!H:H,Planilha1!D:D) -> #N/A
A7: 129441284 | B7: =_xlfn.XLOOKUP(A7,Planilha1!H:H,Planilha1!D:D) -> #N/A
A8: 129599207 | B8: =_xlfn.XLOOKUP(A8,Planilha1!H:H,Planilha1!D:D) -> #N/A
A9: 129834862 | B9: =_xlfn.XLOOKUP(A9,Planilha1!H:H,Planilha1!D:D) -> #N/A | C9: #N/A | D9: Cobrado
A10: 129998580 | B10: =_xlfn.XLOOKUP(A10,Planilha1!H:H,Planilha1!D:D) -> #N/A
A11: 130011908 | B11: =_xlfn.XLOOKUP(A11,Planilha1!H:H,Planilha1!D:D) -> #N/A
A12: 130021579 | B12: =_xlfn.XLOOKUP(A12,Planilha1!H:H,Planilha1!D:D) -> #N/A
A13: 130026730 | B13: =_xlfn.XLOOKUP(A13,Planilha1!H:H,Planilha1!D:D) -> #N/A
A14: 130394687 | B14: =_xlfn.XLOOKUP(A14,Planilha1!H:H,Planilha1!D:D) -> #N/A
A15: 130381891 | B15: =_xlfn.XLOOKUP(A15,Planilha1!H:H,Planilha1!D:D) -> #N/A
A16: 130424524 | B16: =_xlfn.XLOOKUP(A16,Planilha1!H:H,Planilha1!D:D) -> #N/A
A17: 130434836 | B17: =_xlfn.XLOOKUP(A17,Planilha1!H:H,Planilha1!D:D) -> #N/A
A18: 130410391 | B18: =_xlfn.XLOOKUP(A18,Planilha1!H:H,Planilha1!D:D) -> #N/A
A19: 130405533 | B19: =_xlfn.XLOOKUP(A19,Planilha1!H:H,Planilha1!D:D) -> #N/A
A20: 130782231 | B20: =_xlfn.XLOOKUP(A20,Planilha1!H:H,Planilha1!D:D) -> #N/A
A21: 130781514 | B21: =_xlfn.XLOOKUP(A21,Planilha1!H:H,Planilha1!D:D) -> #N/A
... A42: 128922475 | B42: =_xlfn.XLOOKUP(A42,Planilha1!H:H,Planilha1!D:D) -> #N/A
A43: 129012469 | B43: =_xlfn.XLOOKUP(A43,Planilha1!H:H,Planilha1!D:D) -> #N/A | C43: #N/A | D43: Cobrado
A44: 129142868 | B44: =_xlfn.XLOOKUP(A44,Planilha1!H:H,Planilha1!D:D) -> #N/A
A45: 129144984 | B45: =_xlfn.XLOOKUP(A45,Planilha1!H:H,Planilha1!D:D) -> #N/A
A46: 129154680 | B46: =_xlfn.XLOOKUP(A46,Planilha1!H:H,Planilha1!D:D) -> #N/A
A47: 129116738 | B47: =_xlfn.XLOOKUP(A47,Planilha1!H:H,Planilha1!D:D) -> #N/A | C47: #N/A | D47: Cobrado
A48: 129351255 | B48: =_xlfn.XLOOKUP(A48,Planilha1!H:H,Planilha1!D:D) -> #N/A | C48: #N/A | D48: Cobrado
A49: 129548423 | B49: =_xlfn.XLOOKUP(A49,Planilha1!H:H,Planilha1!D:D) -> 666326222
A50: 129568043 | B50: =_xlfn.XLOOKUP(A50,Planilha1!H:H,Planilha1!D:D) -> #N/A
A51: 129557568 | B51: =_xlfn.XLOOKUP(A51,Planilha1!H:H,Planilha1!D:D) -> #N/A
A52: 129599644 | B52: =_xlfn.XLOOKUP(A52,Planilha1!H:H,Planilha1!D:D) -> #N/A | C52: #N/A | D52: Cobrado
A53: 129536777 | B53: =_xlfn.XLOOKUP(A53,Planilha1!H:H,Planilha1!D:D) -> #N/A | C53: #N/A | D53: Cobrado
A54: 130033175 | B54: =_xlfn.XLOOKUP(A54,Planilha1!H:H,Planilha1!D:D) -> #N/A
A55: 130033353 | B55: =_xlfn.XLOOKUP(A55,Planilha1!H:H,Planilha1!D:D) -> #N/A
A56: 130030251 | B56: =_xlfn.XLOOKUP(A56,Planilha1!H:H,Planilha1!D:D) -> #N/A
A57: 130029976 | B57: =_xlfn.XLOOKUP(A57,Planilha1!H:H,Planilha1!D:D) -> 693480505
A58: 130029349 | B58: =_xlfn.XLOOKUP(A58,Planilha1!H:H,Planilha1!D:D) -> #N/A
A59: 130016037 | B59: =_xlfn.XLOOKUP(A59,Planilha1!H:H,Planilha1!D:D) -> #N/A
A60: 130388789 | B60: =_xlfn.XLOOKUP(A60,Planilha1!H:H,Planilha1!D:D) -> #N/A | C60: #N/A | D60: Cobrado
...
